<?xml version="1.0"?>
<robot name="diffbot" xmlns:xacro="http://www.ros.org/wiki/xacro">
  <xacro:property name="base_length" value="0.34"/>
  <xacro:property name="base_width" value="0.26"/>
  <xacro:property name="base_height" value="0.10"/>
  <xacro:property name="wheel_radius" value="0.05"/>
  <xacro:property name="wheel_width" value="0.03"/>
  <xacro:property name="wheel_sep" value="0.22"/>

  <link name="base_footprint"/>

  <link name="base_link">
    <visual>
      <geometry>
        <box size="${base_length} ${base_width} ${base_height}"/>
      </geometry>
      <material name="gray">
        <color rgba="0.5 0.5 0.5 1.0"/>
      </material>
    </visual>
    <collision>
      <geometry>
        <box size="${base_length} ${base_width} ${base_height}"/>
      </geometry>
    </collision>
    <inertial>
      <origin xyz="0 0 0"/>
      <mass value="5.0"/>
      <inertia ixx="0.08" ixy="0.0" ixz="0.0" iyy="0.08" iyz="0.0" izz="0.10"/>
    </inertial>
  </link>

  <joint name="base_footprint_joint" type="fixed">
    <parent link="base_footprint"/>
    <child link="base_link"/>
    <origin xyz="0 0 ${base_height/2}" rpy="0 0 0"/>
  </joint>

  <link name="left_wheel_link">
    <visual>
      <origin xyz="0 0 0" rpy="1.5708 0 0"/>
      <geometry>
        <cylinder radius="${wheel_radius}" length="${wheel_width}"/>
      </geometry>
      <material name="black">
        <color rgba="0.1 0.1 0.1 1.0"/>
      </material>
    </visual>
    <collision>
      <origin xyz="0 0 0" rpy="1.5708 0 0"/>
      <geometry>
        <cylinder radius="${wheel_radius}" length="${wheel_width}"/>
      </geometry>
    </collision>
    <inertial>
      <mass value="0.5"/>
      <inertia ixx="0.001" ixy="0.0" ixz="0.0" iyy="0.001" iyz="0.0" izz="0.001"/>
    </inertial>
  </link>

  <link name="right_wheel_link">
    <visual>
      <origin xyz="0 0 0" rpy="1.5708 0 0"/>
      <geometry>
        <cylinder radius="${wheel_radius}" length="${wheel_width}"/>
      </geometry>
      <material name="black">
        <color rgba="0.1 0.1 0.1 1.0"/>
      </material>
    </visual>
    <collision>
      <origin xyz="0 0 0" rpy="1.5708 0 0"/>
      <geometry>
        <cylinder radius="${wheel_radius}" length="${wheel_width}"/>
      </geometry>
    </collision>
    <inertial>
      <mass value="0.5"/>
      <inertia ixx="0.001" ixy="0.0" ixz="0.0" iyy="0.001" iyz="0.0" izz="0.001"/>
    </inertial>
  </link>

  <joint name="left_wheel_joint" type="continuous">
    <parent link="base_link"/>
    <child link="left_wheel_link"/>
    <origin xyz="0 ${wheel_sep/2} ${-base_height/2}" rpy="0 0 0"/>
    <axis xyz="0 1 0"/>
  </joint>

  <joint name="right_wheel_joint" type="continuous">
    <parent link="base_link"/>
    <child link="right_wheel_link"/>
    <origin xyz="0 ${-wheel_sep/2} ${-base_height/2}" rpy="0 0 0"/>
    <axis xyz="0 1 0"/>
  </joint>

  <link name="lidar_link">
    <visual>
      <geometry>
        <cylinder radius="0.03" length="0.05"/>
      </geometry>
      <material name="blue">
        <color rgba="0.1 0.1 0.8 1.0"/>
      </material>
    </visual>
  </link>

  <joint name="lidar_joint" type="fixed">
    <parent link="base_link"/>
    <child link="lidar_link"/>
    <origin xyz="0.12 0 0.08" rpy="0 0 0"/>
  </joint>

  <gazebo>
    <plugin name="diff_drive" filename="libgazebo_ros_diff_drive.so">
      <left_joint>left_wheel_joint</left_joint>
      <right_joint>right_wheel_joint</right_joint>
      <wheel_separation>${wheel_sep}</wheel_separation>
      <wheel_diameter>${2*wheel_radius}</wheel_diameter>
      <max_wheel_torque>5.0</max_wheel_torque>
      <max_wheel_acceleration>4.0</max_wheel_acceleration>
      <publish_odom>true</publish_odom>
      <publish_odom_tf>true</publish_odom_tf>
      <publish_wheel_tf>false</publish_wheel_tf>
      <odometry_topic>odom</odometry_topic>
      <odometry_frame>odom</odometry_frame>
      <robot_base_frame>base_link</robot_base_frame>
      <command_topic>cmd_vel</command_topic>
    </plugin>
  </gazebo>

  <gazebo reference="lidar_link">
    <sensor name="scan" type="ray">
      <always_on>true</always_on>
      <visualize>true</visualize>
      <update_rate>10.0</update_rate>
      <ray>
        <scan>
          <horizontal>
            <samples>720</samples>
            <resolution>1</resolution>
            <min_angle>-3.14159</min_angle>
            <max_angle>3.14159</max_angle>
          </horizontal>
        </scan>
        <range>
          <min>0.12</min>
          <max>12.0</max>
          <resolution>0.01</resolution>
        </range>
      </ray>
      <plugin name="lidar_plugin" filename="libgazebo_ros_ray_sensor.so">
        <ros>
          <remapping>~/out:=scan</remapping>
        </ros>
        <output_type>sensor_msgs/LaserScan</output_type>
        <frame_name>lidar_link</frame_name>
      </plugin>
    </sensor>
  </gazebo>
</robot>
